Workbook

Sheet Hoevelaken-adressenlijst
A1: postcode | B1: huisnummer | C1: toevoeging | D1: straat | E1: plaats | F1: Aantal | G1: P Geb | H1: Longitude | I1: Latitude
A2: 3871AD | B2: 2 | C2: A | D2: Oosterdorpsstraat | E2: Hoevelaken | F2: =COUNTIFS($D$2:D2,D2) -> 1 | G2: =LEFT(A2,5) -> 3871A | H2: 5.4586321 | I2: 52.175837 | J2: 3871 AD | K2: 2a | L2: Oosterdorpsstraat | M2: Hoevelaken
A3: 3871AD | B3: 4 | C3: A | D3: Oosterdorpsstraat | E3: Hoevelaken | F3: =COUNTIFS($D$2:D3,D3) -> 2 | G3: =LEFT(A3,5) -> 3871A | H3: 5.4588457 | I3: 52.175815 | J3: 3871 AD | K3: 4a | L3: Oosterdorpsstraat | M3: Hoevelaken
A4: 3871AD | B4: 4 | D4: Oosterdorpsstraat | E4: Hoevelaken | F4: =COUNTIFS($D$2:D4,D4) -> 3 | G4: =LEFT(A4,5) -> 3871A | H4: 5.4586478 | I4: 52.175794 | J4: 3871 AD | K4: 4 | L4: Oosterdorpsstraat | M4: Hoevelaken
A5: 3871AD | B5: 6 | C5: A | D5: Oosterdorpsstraat | E5: Hoevelaken | F5: =COUNTIFS($D$2:D5,D5) -> 4 | G5: =LEFT(A5,5) -> 3871A | H5: 5.4589088 | I5: 52.175677 | J5: 3871 AD | K5: 6a | L5: Oosterdorpsstraat | M5: Hoevelaken
A6: 3871AD | B6: 6 | D6: Oosterdorpsstraat | E6: Hoevelaken | F6: =COUNTIFS($D$2:D6,D6) -> 5 | G6: =LEFT(A6,5) -> 3871A | H6: 5.4588772 | I6: 52.175753 | J6: 3871 AD | K6: 6 | L6: Oosterdorpsstraat | M6: Hoevelaken
A7: 3871AD | B7: 8 | D7: Oosterdorpsstraat | E7: Hoevelaken | F7: =COUNTIFS($D$2:D7,D7) -> 6 | G7: =LEFT(A7,5) -> 3871A | H7: 5.4586656 | I7: 52.175753 | J7: 3871 AD | K7: 8 | L7: Oosterdorpsstraat | M7: Hoevelaken
A8: 3871AD | B8: 10 | D8: Oosterdorpsstraat | E8: Hoevelaken | F8: =COUNTIFS($D$2:D8,D8) -> 7 | G8: =LEFT(A8,5) -> 3871A | H8: 5.4588138 | I8: 52.175661 | J8: 3871 AD | K8: 10 | L8: Oosterdorpsstraat | M8: Hoevelaken
A9: 3871AD | B9: 12 | D9: Oosterdorpsstraat | E9: Hoevelaken | F9: =COUNTIFS($D$2:D9,D9) -> 8 | G9: =LEFT(A9,5) -> 3871A | H9: 5.459359 | I9: 52.175936 | J9: 3871 AD | K9: 12 | L9: Oosterdorpsstraat | M9: Hoevelaken
A10: 3871AD | B10: 14 | D10: Oosterdorpsstraat | E10: Hoevelaken | F10: =COUNTIFS($D$2:D10,D10) -> 9 | G10: =LEFT(A10,5) -> 3871A | H10: 5.4593693 | I10: 52.175895 | J10: 3871 AD | K10: 14 | L10: Oosterdorpsstraat | M10: Hoevelaken
A11: 3871AD | B11: 18 | D11: Oosterdorpsstraat | E11: Hoevelaken | F11: =COUNTIFS($D$2:D11,D11) -> 10 | G11: =LEFT(A11,5) -> 3871A | H11: 5.4604029 | I11: 52.175975 | J11: 3871 AD | K11: 18 | L11: Oosterdorpsstraat | M11: Hoevelaken
A12: 3871AD | B12: 22 | C12: A | D12: Oosterdorpsstraat | E12: Hoevelaken | F12: =COUNTIFS($D$2:D12,D12) -> 11 | G12: =LEFT(A12,5) -> 3871A | H12: 5.4609585 | I12: 52.17601 | J12: 3871 AD | K12: 22a | L12: Oosterdorpsstraat | M12: Hoevelaken
A13: 3871AD | B13: 22 | D13: Oosterdorpsstraat | E13: Hoevelaken | F13: =COUNTIFS($D$2:D13,D13) -> 12 | G13: =LEFT(A13,5) -> 3871A | H13: 5.4607538 | I13: 52.176001 | J13: 3871 AD | K13: 22 | L13: Oosterdorpsstraat | M13: Hoevelaken
A14: 3871AD | B14: 24 | D14: Oosterdorpsstraat | E14: Hoevelaken | F14: =COUNTIFS($D$2:D14,D14) -> 13 | G14: =LEFT(A14,5) -> 3871A | H14: 5.4613093 | I14: 52.175956 | J14: 3871 AD | K14: 24 | L14: Oosterdorpsstraat | M14: Hoevelaken
A15: 3871AD | B15: 26 | D15: Oosterdorpsstraat | E15: Hoevelaken | F15: =COUNTIFS($D$2:D15,D15) -> 14 | G15: =LEFT(A15,5) -> 3871A | H15: 5.4616893 | I15: 52.17592 | J15: 3871 AD | K15: 26 | L15: Oosterdorpsstraat | M15: Hoevelaken
A16: 3871AD | B16: 28 | D16: Oosterdorpsstraat | E16: Hoevelaken | F16: =COUNTIFS($D$2:D16,D16) -> 15 | G16: =LEFT(A16,5) -> 3871A | H16: 5.4618939 | I16: 52.175884 | J16: 3871 AD | K16: 28 | L16: Oosterdorpsstraat | M16: Hoevelaken
A17: 3871AD | B17: 32 | D17: Oosterdorpsstraat | E17: Hoevelaken | F17: =COUNTIFS($D$2:D17,D17) -> 16 | G17: =LEFT(A17,5) -> 3871A | H17: 5.4621278 | I17: 52.175866 | J17: 3871 AD | K17: 32 | L17: Oosterdorpsstraat | M17: Hoevelaken
A18: 3871AD | B18: 34 | D18: Oosterdorpsstraat | E18: Hoevelaken | F18: =COUNTIFS($D$2:D18,D18) -> 17 | G18: =LEFT(A18,5) -> 3871A | H18: 5.4621863 | I18: 52.175857 | J18: 3871 AD | K18: 34 | L18: Oosterdorpsstraat | M18: Hoevelaken
A19: 3871AD | B19: 36 | D19: Oosterdorpsstraat | E19: Hoevelaken | F19: =COUNTIFS($D$2:D19,D19) -> 18 | G19: =LEFT(A19,5) -> 3871A | H19: 5.4622301 | I19: 52.175857 | J19: 3871 AD | K19: 36 | L19: Oosterdorpsstraat | M19: Hoevelaken
A20: 3871AD | B20: 40 | D20: Oosterdorpsstraat | E20: Hoevelaken | F20: =COUNTIFS($D$2:D20,D20) -> 19 | G20: =LEFT(A20,5) -> 3871A | H20: 5.46299 | I20: 52.175658 | J20: 3871 AD | K20: 40 | L20: Oosterdorpsstraat | M20: Hoevelaken
A21: 3871AD | B21: 46 | D21: Oosterdorpsstraat | E21: Hoevelaken | F21: =COUNTIFS($D$2:D21,D21) -> 20 | G21: =LEFT(A21,5) -> 3871A | H21: 5.463253 | I21: 52.175577 | J21: 3871 AD | K21: 46 | L21: Oosterdorpsstraat | M21: Hoevelaken
A22: 3871AD | B22: 48 | D22: Oosterdorpsstraat | E22: Hoevelaken | F22: =COUNTIFS($D$2:D22,D22) -> 21 | G22: =LEFT(A22,5) -> 3871A | H22: 5.46356 | I22: 52.175568 | J22: 3871 AD | K22: 48 | L22: Oosterdorpsstraat | M22: Hoevelaken
A23: 3871AE | B23: 50 | D23: Oosterdorpsstraat | E23: Hoevelaken | F23: =COUNTIFS($D$2:D23,D23) -> 22 | G23: =LEFT(A23,5) -> 3871A | H23: 5.4637207 | I23: 52.175532 | J23: 3871 AE | K23: 50 | L23: Oosterdorpsstraat | M23: Hoevelaken
A24: 3871AE | B24: 52 | D24: Oosterdorpsstraat | E24: Hoevelaken | F24: =COUNTIFS($D$2:D24,D24) -> 23 | G24: =LEFT(A24,5) -> 3871A | H24: 5.4639692 | I24: 52.175478 | J24: 3871 AE | K24: 52 | L24: Oosterdorpsstraat | M24: Hoevelaken
... A44: 3871AG | B44: 100 | D44: Oosterdorpsstraat | E44: Hoevelaken | F44: =COUNTIFS($D$2:D44,D44) -> 43 | G44: =LEFT(A44,5) -> 3871A | H44: 5.4680106 | I44: 52.175194 | J44: 3871 AG | K44: 100 | L44: Oosterdorpsstraat | M44: Hoevelaken
A45: 3871AG | B45: 102 | C45: A | D45: Oosterdorpsstraat | E45: Hoevelaken | F45: =COUNTIFS($D$2:D45,D45) -> 44 | G45: =LEFT(A45,5) -> 3871A | H45: 5.4684567 | I45: 52.175169 | J45: 3871 AG | K45: 102a | L45: Oosterdorpsstraat | M45: Hoevelaken
A46: 3871AG | B46: 104 | D46: Oosterdorpsstraat | E46: Hoevelaken | F46: =COUNTIFS($D$2:D46,D46) -> 45 | G46: =LEFT(A46,5) -> 3871A | H46: 5.4687636 | I46: 52.175106 | J46: 3871 AG | K46: 104 | L46: Oosterdorpsstraat | M46: Hoevelaken
A47: 3871AG | B47: 106 | D47: Oosterdorpsstraat | E47: Hoevelaken | F47: =COUNTIFS($D$2:D47,D47) -> 46 | G47: =LEFT(A47,5) -> 3871A | H47: 5.4689975 | I47: 52.175106 | J47: 3871 AG | K47: 106 | L47: Oosterdorpsstraat | M47: Hoevelaken
A48: 3871AG | B48: 108 | D48: Oosterdorpsstraat | E48: Hoevelaken | F48: =COUNTIFS($D$2:D48,D48) -> 47 | G48: =LEFT(A48,5) -> 3871A | H48: 5.4692314 | I48: 52.175097 | J48: 3871 AG | K48: 108 | L48: Oosterdorpsstraat | M48: Hoevelaken
A49: 3871AG | B49: 110 | D49: Oosterdorpsstraat | E49: Hoevelaken | F49: =COUNTIFS($D$2:D49,D49) -> 48 | G49: =LEFT(A49,5) -> 3871A | H49: 5.4695113 | I49: 52.175122 | J49: 3871 AG | K49: 110 | L49: Oosterdorpsstraat | M49: Hoevelaken
A50: 3871AG | B50: 112 | D50: Oosterdorpsstraat | E50: Hoevelaken | F50: =COUNTIFS($D$2:D50,D50) -> 49 | G50: =LEFT(A50,5) -> 3871A | H50: 5.4696749 | I50: 52.175139 | J50: 3871 AG | K50: 112 | L50: Oosterdorpsstraat | M50: Hoevelaken
A51: 3871AG | B51: 114 | D51: Oosterdorpsstraat | E51: Hoevelaken | F51: =COUNTIFS($D$2:D51,D51) -> 50 | G51: =LEFT(A51,5) -> 3871A | H51: 5.4697606 | I51: 52.175121 | J51: 3871 AG | K51: 114 | L51: Oosterdorpsstraat | M51: Hoevelaken
A52: 3871AG | B52: 116 | D52: Oosterdorpsstraat | E52: Hoevelaken | F52: =COUNTIFS($D$2:D52,D52) -> 51 | G52: =LEFT(A52,5) -> 3871A | H52: 5.4698445 | I52: 52.175108 | J52: 3871 AG | K52: 116 | L52: Oosterdorpsstraat | M52: Hoevelaken
A53: 3871AG | B53: 118 | D53: Oosterdorpsstraat | E53: Hoevelaken | F53: =COUNTIFS($D$2:D53,D53) -> 52 | G53: =LEFT(A53,5) -> 3871A | H53: 5.4702401 | I53: 52.175087 | J53: 3871 AG | K53: 118 | L53: Oosterdorpsstraat | M53: Hoevelaken
A54: 3871AG | B54: 120 | D54: Oosterdorpsstraat | E54: Hoevelaken | F54: =COUNTIFS($D$2:D54,D54) -> 53 | G54: =LEFT(A54,5) -> 3871A | H54: 5.4703499 | I54: 52.17512 | J54: 3871 AG | K54: 120 | L54: Oosterdorpsstraat | M54: Hoevelaken
A55: 3871AG | B55: 122 | C55: A | D55: Oosterdorpsstraat | E55: Hoevelaken | F55: =COUNTIFS($D$2:D55,D55) -> 54 | G55: =LEFT(A55,5) -> 3871A | H55: 5.4709795 | I55: 52.175124 | J55: 3871 AG | K55: 122a | L55: Oosterdorpsstraat | M55: Hoevelaken
A56: 3871AG | B56: 122 | D56: Oosterdorpsstraat | E56: Hoevelaken | F56: =COUNTIFS($D$2:D56,D56) -> 55 | G56: =LEFT(A56,5) -> 3871A | H56: 5.4706868 | I56: 52.175104 | J56: 3871 AG | K56: 122 | L56: Oosterdorpsstraat | M56: Hoevelaken
A57: 3871AG | B57: 124 | D57: Oosterdorpsstraat | E57: Hoevelaken | F57: =COUNTIFS($D$2:D57,D57) -> 56 | G57: =LEFT(A57,5) -> 3871A | H57: 5.4712635 | I57: 52.175113 | J57: 3871 AG | K57: 124 | L57: Oosterdorpsstraat | M57: Hoevelaken
A58: 3871AG | B58: 124 | C58: A | D58: Oosterdorpsstraat | E58: Hoevelaken | F58: =COUNTIFS($D$2:D58,D58) -> 57 | G58: =LEFT(A58,5) -> 3871A | H58: 5.4713336 | I58: 52.175146 | J58: 3871 AG | K58: 124a | L58: Oosterdorpsstraat | M58: Hoevelaken
A59: 3871AG | B59: 126 | D59: Oosterdorpsstraat | E59: Hoevelaken | F59: =COUNTIFS($D$2:D59,D59) -> 58 | G59: =LEFT(A59,5) -> 3871A | H59: 5.4715367 | I59: 52.175144 | J59: 3871 AG | K59: 126 | L59: Oosterdorpsstraat | M59: Hoevelaken
...

Sheet Blad1
A1: # huizen | B1: Straat | C1: bezorger
A2: 10 | B2: Andreaslaan | C2: Fridtjof | D2: =VLOOKUP(B2,'Hoevelaken-adressenlijst'!$A$1:$E$1739,1) -> 3871VM
A3: 6 | B3: Anjerlaan | C3: JanWillem | D3: =VLOOKUP(B3,'Hoevelaken-adressenlijst'!$A$1:$E$1739,1) -> 3871VM
A4: 29 | B4: Asterlaan | C4: Pieter | D4: =VLOOKUP(B4,'Hoevelaken-adressenlijst'!$A$1:$E$1739,1) -> 3871VM
A5: 28 | B5: Beatrixlaan | C5: Monique | D5: =VLOOKUP(B5,'Hoevelaken-adressenlijst'!$A$1:$E$1739,1) -> 3871VM
A6: 1 | B6: Beekmaten | C6: Fridtjof | D6: =VLOOKUP(B6,'Hoevelaken-adressenlijst'!$A$1:$E$1739,1) -> 3871VM
A7: 5 | B7: Bernhardlaan | C7: Monique | D7: =VLOOKUP(B7,'Hoevelaken-adressenlijst'!$A$1:$E$1739,1) -> 3871VM
A8: 5 | B8: Beukenlaan | D8: =VLOOKUP(B8,'Hoevelaken-adressenlijst'!$A$1:$E$1739,1) -> 3871VM
A9: 8 | B9: Beverdam | C9: Pieter | D9: =VLOOKUP(B9,'Hoevelaken-adressenlijst'!$A$1:$E$1739,1) -> 3871VM
A10: 12 | B10: Bijenvlucht | C10: Pieter | D10: =VLOOKUP(B10,'Hoevelaken-adressenlijst'!$A$1:$E$1739,1) -> 3871VM
A11: 23 | B11: Christinapad | C11: Lieske | D11: =VLOOKUP(B11,'Hoevelaken-adressenlijst'!$A$1:$E$1739,1) -> 3871VM
A12: 14 | B12: Clauslaan | C12: Lieske | D12: =VLOOKUP(B12,'Hoevelaken-adressenlijst'!$A$1:$E$1739,1) -> 3871VM
A13: 8 | B13: Constantijngaarde | C13: Lieske | D13: =VLOOKUP(B13,'Hoevelaken-adressenlijst'!$A$1:$E$1739,1) -> 3871VM
A14: 2 | B14: Crocuslaan | D14: =VLOOKUP(B14,'Hoevelaken-adressenlijst'!$A$1:$E$1739,1) -> 3871VM
A15: 15 | B15: Dillenburg | C15: Lieske | D15: =VLOOKUP(B15,'Hoevelaken-adressenlijst'!$A$1:$E$1739,1) -> 3871VM
A16: 38 | B16: Eiberlaan | C16: René | D16: =VLOOKUP(B16,'Hoevelaken-adressenlijst'!$A$1:$E$1739,1) -> 3871VM
A17: 48 | B17: Elzenlaan | C17: Fridtjof | D17: =VLOOKUP(B17,'Hoevelaken-adressenlijst'!$A$1:$E$1739,1) -> 3871VM
A18: 6 | B18: Emmalaan | C18: Monique | D18: =VLOOKUP(B18,'Hoevelaken-adressenlijst'!$A$1:$E$1739,1) -> 3871VM
A19: 54 | B19: Frans Tromplaan | C19: JanWillem | D19: =VLOOKUP(B19,'Hoevelaken-adressenlijst'!$A$1:$E$1739,1) -> 3871VM
A20: 14 | B20: Gravenhof | C20: Lieske | D20: =VLOOKUP(B20,'Hoevelaken-adressenlijst'!$A$1:$E$1739,1) -> 3871VM
A21: 16 | B21: Havikshorst | C21: Pieter | D21: =VLOOKUP(B21,'Hoevelaken-adressenlijst'!$A$1:$E$1739,1) -> 3871VM
A22: 7 | B22: Hazeleger | C22: Pieter | D22: =VLOOKUP(B22,'Hoevelaken-adressenlijst'!$A$1:$E$1739,1) -> 3871VM
A23: 2 | B23: Hemelricplaats | C23: Fridtjof | D23: =VLOOKUP(B23,'Hoevelaken-adressenlijst'!$A$1:$E$1739,1) -> 3871VM
A24: 10 | B24: Heribertlaan | D24: =VLOOKUP(B24,'Hoevelaken-adressenlijst'!$A$1:$E$1739,1) -> 3871VM
A25: 2 | B25: Horstpad | C25: Pieter | D25: =VLOOKUP(B25,'Hoevelaken-adressenlijst'!$A$1:$E$1739,1) -> 3871VM
A26: 22 | B26: Horstweg | C26: Lieske | D26: =VLOOKUP(B26,'Hoevelaken-adressenlijst'!$A$1:$E$1739,1) -> 3871VM
A27: 17 | B27: Ibislaan | C27: René | D27: =VLOOKUP(B27,'Hoevelaken-adressenlijst'!$A$1:$E$1739,1) -> 3871VM
A28: 8 | B28: Irenepad | C28: Lieske | D28: =VLOOKUP(B28,'Hoevelaken-adressenlijst'!$A$1:$E$1739,1) -> 3871VM
A29: 5 | B29: J.J.A. Goeverneurlaan | C29: Tijmen | D29: =VLOOKUP(B29,'Hoevelaken-adressenlijst'!$A$1:$E$1739,1) -> 3871VM
A30: 20 | B30: Johan Frisohof | C30: Lieske | D30: =VLOOKUP(B30,'Hoevelaken-adressenlijst'!$A$1:$E$1739,1) -> 3871VM
A31: 71 | B31: Julianalaan | C31: Pieter | D31: =VLOOKUP(B31,'Hoevelaken-adressenlijst'!$A$1:$E$1739,1) -> 3871VM
A32: 8 | B32: Kastanjelaan | C32: Fridtjof | D32: =VLOOKUP(B32,'Hoevelaken-adressenlijst'!$A$1:$E$1739,1) -> 3871VM
A33: 16 | B33: Kievitlaan | C33: Tijmen | D33: =VLOOKUP(B33,'Hoevelaken-adressenlijst'!$A$1:$E$1739,1) -> 3871VM
A34: 57 | B34: Kijftenbeltlaan | C34: Fridtjof | D34: =VLOOKUP(B34,'Hoevelaken-adressenlijst'!$A$1:$E$1739,1) -> 3871VM
A35: 47 | B35: Klaprooslaan | C35: JanWillem | D35: =VLOOKUP(B35,'Hoevelaken-adressenlijst'!$A$1:$E$1739,1) -> 3871VM
A36: 2 | B36: Koninginneweg | D36: =VLOOKUP(B36,'Hoevelaken-adressenlijst'!$A$1:$E$1739,1) -> 3871VM
A37: 12 | B37: Koningshof | C37: Monique | D37: =VLOOKUP(B37,'Hoevelaken-adressenlijst'!$A$1:$E$1739,1) -> 3871VM
A38: 14 | B38: Koolmeeslaan | C38: Tijmen | D38: =VLOOKUP(B38,'Hoevelaken-adressenlijst'!$A$1:$E$1739,1) -> 3871VM
A39: 5 | B39: Korenbloemlaan | D39: =VLOOKUP(B39,'Hoevelaken-adressenlijst'!$A$1:$E$1739,1) -> 3871VM
A40: 6 | B40: Laantje van Hilhorst | D40: =VLOOKUP(B40,'Hoevelaken-adressenlijst'!$A$1:$E$1739,1) -> 3871VM
...

Sheet Blad2
A1: postcode | B1: huisnummer | C1: toevoeging | D1: straat | E1: plaats
A2: 3871MA | B2: 1 | D2: Heribertlaan | E2: Hoevelaken | F2: 48 | G2: 3871M
A3: 3871MA | B3: 2 | D3: Heribertlaan | E3: Hoevelaken | F3: 44 | G3: 3871M
A4: 3871MA | B4: 3 | D4: Heribertlaan | E4: Hoevelaken | F4: 49 | G4: 3871M
A5: 3871MA | B5: 4 | D5: Heribertlaan | E5: Hoevelaken | F5: 50 | G5: 3871M
A6: 3871MA | B6: 5 | D6: Heribertlaan | E6: Hoevelaken | F6: 47 | G6: 3871M
A7: 3871MA | B7: 6 | D7: Heribertlaan | E7: Hoevelaken | F7: 45 | G7: 3871M
A8: 3871MA | B8: 7 | D8: Heribertlaan | E8: Hoevelaken | F8: 46 | G8: 3871M
A9: 3871MA | B9: 8 | D9: Heribertlaan | E9: Hoevelaken | F9: 51 | G9: 3871M
A10: 3871MA | B10: 9 | D10: Heribertlaan | E10: Hoevelaken | F10: 43 | G10: 3871M
A11: 3871MA | B11: 10 | D11: Heribertlaan | E11: Hoevelaken | F11: 42 | G11: 3871M
A12: 3871MB | B12: 1 | D12: Andreaslaan | E12: Hoevelaken | F12: 5 | G12: 3871M
A13: 3871MB | B13: 2 | D13: Andreaslaan | E13: Hoevelaken | F13: 6 | G13: 3871M
... A97: 3871TD | B97: 51 | D97: van Dedemlaan | E97: Hoevelaken | F97: 122 | G97: 3871T
