Workbook

Sheet hoevelaken-contacten
A1: E-mail adres | B1: Voornaam | C1: Achternaam | D1: Telefoonnummer | E1: Straatnaam | F1: Huisnummer | G1: Postcode | H1: Woonplaats | I1: Ontvang mailings | J1: Lid | K1: Labels | L1: Rol | M1: Projecten | N1: Agenda items
A2: jos@buurkracht.nl | B2: Jos | C2: Morren | D2: 65551345 | I2: Ja | J2: Nee | L2: Beheerder
A3: rsh.kwee@gmail.com | B3: René | C3: Kwee | D3: 0651174310 | E3: van Dedemlaan | F3: 13 | G3: 3871TD | H3: Hoevelaken | I3: Ja | J3: Nee | L3: Beheerder | M3: Actie warmtescans
A4: info@famguth.nl | B4: Fridtjof | C4: Guth | D4: 0622395427 | E4: Pastoorakker | F4: 37 | G4: 3871MN | H4: Hoevelaken | I4: Ja | J4: Nee | L4: Lid | M4: Actie warmtescans
A5: w.j.fontein@kpnmail.nl | B5: Willem | C5: Fontein | D5: 0654930265 | I5: Ja | J5: Nee | L5: Lid
A6: Mark.de.Vos70@gmail.com | B6: Mark | C6: de Vos | D6: 0631004442 | I6: Ja | J6: Nee | L6: Lid | M6: Actie warmtescans
A7: moniquesprullenbak@gmail.com | B7: Monique | C7: Spaans | D7: 0618584171 | I7: Ja | J7: Nee | L7: Lid
A8: resa_vdbunt@hotmail.com | B8: Resa | C8: Van den Bunt | D8: 0620360637 | I8: Ja | J8: Nee | L8: Lid
A9: ge2.schaeffer@gmail.com | B9: Gé | C9: Schaeffer | D9: 0622482339 | I9: Ja | J9: Nee | L9: Lid
A10: elles1966@live.nl | B10: Elles | C10: van der Loo | I10: Ja | J10: Nee | L10: Lid
A11: Manuvanessen@planet.nl | B11: Manu | C11: van Essen | I11: Ja | J11: Nee | L11: Lid
A12: mmjvv@hotmail.com | B12: Mina | C12: vV | I12: Ja | J12: Nee | L12: Lid
A13: gm.top1950@gmail.com | B13: Bertha | C13: Top | D13: 0630093672 | I13: Ja | J13: Nee | L13: Lid
A14: andre.vanbeekhuizen@gmail.com | B14: André | C14: van Beekhuizen | D14: 0655010530 | I14: Ja | J14: Nee | L14: Lid
A15: marcoblankestijn@gmail.com | B15: Marco | C15: Blankestijn | D15: 0639030629 | I15: Ja | J15: Nee | L15: Lid | M15: Actie warmtescans
A16: diederik@samen100.com | B16: Diederik | C16: Van Essen | D16: 06 54328466 | I16: Ja | J16: Nee | L16: Lid
A17: m.r.meijnderts@gmail.com | B17: Max | C17: Meijnderts | D17: 0622120489 | I17: Ja | J17: Nee | L17: Lid
A18: gvork67@gmail.com | B18: GAJ | C18: VORK | D18: 0620859542 | E18: Julianalaan | F18: 67 | G18: 3871 VG | H18: HOEVELAKEN | I18: Ja | J18: Nee | L18: Lid
A19: dickblank35@gmail.com | B19: Dick | C19: Blanj | D19: 0636549502 | I19: Ja | J19: Nee | L19: Lid
A20: mtd_jonker@hotmail.com | B20: Martijn | C20: Jonker | I20: Ja | J20: Nee | L20: Lid
A21: macsprout@hotmail.com | B21: Mac | C21: Sprout | D21: 0622556872 | I21: Ja | J21: Nee | L21: Lid
A22: bam.boersma@online.nl | B22: Bam | C22: Boersma | D22: 0623479560 | E22: Roggeakker | F22: 42 | G22: 3871 NV | H22: Hoevelaken | I22: Ja | J22: Nee | L22: Lid | M22: Actie warmtescans
A23: hermie@live.nl | B23: Herman | C23: van der Meij | D23: 0623895920 | E23: Pastoorakker | F23: 31 | G23: 3871 MN | H23: Hoevelaken | I23: Ja | J23: Nee | L23: Lid | M23: Actie warmtescans
A24: menmkip@gmail.com | B24: Martijn | C24: Kip | D24: 0628876854 | E24: Mulderslaantje | F24: 6 | G24: 3871 BP | H24: Hoevelaken | I24: Ja | J24: Nee | L24: Lid | M24: Actie warmtescans
A25: albertvandijk@hotmail.com | B25: Albert | C25: van Dijk | D25: 0332536849 | E25: Pastoorakker | F25: 23 | G25: 3871MN | H25: Hoevelaken | I25: Ja | J25: Nee | L25: Lid | M25: Actie warmtescans
A26: marjolijnenruud@hotmail.com | B26: Ruud | C26: Van Tamelen | D26: 0652458568 | E26: Twaalfmorgenland | F26: 12 | G26: 3871ML | H26: Hoevelaken | I26: Ja | J26: Nee | L26: Lid | M26: Actie warmtescans
A27: jrwollie@gmail.com | B27: Rob | C27: Wolthuis | D27: 0640317660 | E27: Elzenlaan | F27: 36 | G27: 3871bl | H27: Hoevelaken | I27: Nee | J27: Nee | L27: Lid | M27: Actie warmtescans
A28: esthervanbuuren@live.nl | B28: Esther | C28: Van Buuren | D28: 0612100122 | E28: Parklaan | F28: 17 | G28: 3871EE | H28: HOEVELAKEN | I28: Ja | J28: Nee | L28: Lid | M28: Actie warmtescans
A29: herman@taalchecken.nl | I29: Ja | J29: Nee | L29: Lid | M29: Actie warmtescans
A30: martin2287@proton.me | I30: Ja | J30: Nee | L30: Lid | M30: Actie warmtescans
A31: michielblok09@gmail.com | B31: Michiel | C31: Blok | D31: 0620654538 | E31: Christinapad | F31: 8 | G31: 3871CJ | H31: Hoevelaken | I31: Ja | J31: Nee | L31: Lid | M31: Actie warmtescans
A32: lieske.feije@kpnmail.nl | B32: Lieske en Feije | C32: Duim | D32: 06 44296945 | E32: Irenepad | F32: 6 | G32: 3871 JW | H32: Hoevelaken | I32: Ja | J32: Nee | L32: Lid | M32: Actie warmtescans
A33: eloo.1@kpnmail.nl | B33: Erik | C33: van der Loo | D33: 0653813296 | E33: Willem de Zwijgerlaan | F33: 10 | G33: 3871CE | H33: Hoevelaken | I33: Ja | J33: Nee | L33: Lid | M33: Actie warmtescans
A34: kokhj@kpnmail.nl | I34: Ja | J34: Nee | L34: Lid | M34: Actie warmtescans
A35: dolfhuybers@gmail.com | B35: Dolf | C35: Huybers | E35: Van Dedemlaan | F35: 27 | G35: 3971TD | H35: Hoevelaken | I35: Nee | J35: Nee | L35: Lid | M35: Actie warmtescans
A36: fj.soetens@kpnmail.nl | B36: Frank | C36: Soetens | D36: 0332867880 | E36: Gravenhof | F36: 5 | G36: 3871cn | H36: Hoevelaken | I36: Ja | J36: Nee | L36: Lid | M36: Actie warmtescans
A37: Fam.vdkamp@outlook.com | B37: Richard | C37: van de Kamp | D37: 0636323315 | E37: Willem de Zwijgerlaan | F37: 1 | G37: 3871 ce | H37: Hoevelaken | I37: Ja | J37: Nee | L37: Lid | M37: Actie warmtescans
A38: jeroen.sturrus@gmail.com | I38: Ja | J38: Nee | L38: Lid | M38: Actie warmtescans
A39: timvanaart@hotmail.com | B39: Tim | C39: van Aart | E39: Nassaulaan | F39: 57 | G39: 3871CW | H39: Hoevelaken | I39: Nee | J39: Nee | L39: Lid | M39: Actie warmtescans
A40: roelckiers@upcmail.nl | B40: Roel | C40: Kiers- Assendorp | D40: 0332537177 | E40: Horstweg | F40: 12 | G40: 3871 KP | H40: Hoevelaken. | I40: Nee | J40: Nee | L40: Lid | M40: Actie warmtescans
...

Sheet Warmtescan
A1: postcode | B1: huisnummer | C1: toevoeging | D1: straat | E1: plaats | F1: Aantal | G1: P Geb | H1: Longitude | I1: Latitude | N1: Voornaam | O1: Achternaam | P1: Telefoon | Q1: Projecten
A2: 3871TD | B2: 13 | D2: van Dedemlaan | E2: Hoevelaken | N2: René | O2: Kwee | P2: 0651174310 | Q2: Actie warmtescans
A3: 3871MN | B3: 37 | D3: Pastoorakker | E3: Hoevelaken | N3: Fridtjof | O3: Guth | P3: 0622395427 | Q3: Actie warmtescans
A4: 0 | B4: 0 | D4: 0 | E4: 0 | N4: Mark | O4: de Vos | P4: 0631004442 | Q4: Actie warmtescans
A5: 0 | B5: 0 | D5: 0 | E5: 0 | N5: Marco | O5: Blankestijn | P5: 0639030629 | Q5: Actie warmtescans
A6: 3871 NV | B6: 42 | D6: Roggeakker | E6: Hoevelaken | N6: Bam | O6: Boersma | P6: 0623479560 | Q6: Actie warmtescans
A7: 3871 MN | B7: 31 | D7: Pastoorakker | E7: Hoevelaken | N7: Herman | O7: van der Meij | P7: 0623895920 | Q7: Actie warmtescans
A8: 3871 BP | B8: 6 | D8: Mulderslaantje | E8: Hoevelaken | N8: Martijn | O8: Kip | P8: 0628876854 | Q8: Actie warmtescans
A9: 3871MN | B9: 23 | D9: Pastoorakker | E9: Hoevelaken | N9: Albert | O9: van Dijk | P9: 0332536849 | Q9: Actie warmtescans
A10: 3871ML | B10: 12 | D10: Twaalfmorgenland | E10: Hoevelaken | N10: Ruud | O10: Van Tamelen | P10: 0652458568 | Q10: Actie warmtescans
A11: 3871bl | B11: 36 | D11: Elzenlaan | E11: Hoevelaken | N11: Rob | O11: Wolthuis | P11: 0640317660 | Q11: Actie warmtescans
A12: 3871EE | B12: 17 | D12: Parklaan | E12: HOEVELAKEN | N12: Esther | O12: Van Buuren | P12: 0612100122 | Q12: Actie warmtescans
A13: 3871CJ | B13: 8 | D13: Christinapad | E13: Hoevelaken | N13: Michiel | O13: Blok | P13: 0620654538 | Q13: Actie warmtescans
A14: 3871 JW | B14: 6 | D14: Irenepad | E14: Hoevelaken | N14: Lieske en Feije | O14: Duim | P14: 06 44296945 | Q14: Actie warmtescans
A15: 3871CE | B15: 10 | D15: Willem de Zwijgerlaan | E15: Hoevelaken | N15: Erik | O15: van der Loo | P15: 0653813296 | Q15: Actie warmtescans
A16: 3971TD | B16: 27 | D16: Van Dedemlaan | E16: Hoevelaken | N16: Dolf | O16: Huybers | P16: 0 | Q16: Actie warmtescans
A17: 3871cn | B17: 5 | D17: Gravenhof | E17: Hoevelaken | N17: Frank | O17: Soetens | P17: 0332867880 | Q17: Actie warmtescans
A18: 3871 ce | B18: 1 | D18: Willem de Zwijgerlaan | E18: Hoevelaken | N18: Richard | O18: van de Kamp | P18: 0636323315 | Q18: Actie warmtescans
A19: 3871CW | B19: 57 | D19: Nassaulaan | E19: Hoevelaken | N19: Tim | O19: van Aart | P19: 0 | Q19: Actie warmtescans
A20: 3871 KP | B20: 12 | D20: Horstweg | E20: Hoevelaken. | N20: Roel | O20: Kiers- Assendorp | P20: 0332537177 | Q20: Actie warmtescans
A21: 0 | B21: 18 | D21: Oosterdorpsstraat | E21: Hoevelaken | N21: A.M | O21: André | P21: 0651587311 | Q21: Actie warmtescans
A22: 3871DB | B22: 16 | D22: Prinsenhof | E22: Hoevelaken | N22: Tobias | O22: van Garderen | P22: 0644966286 | Q22: Actie warmtescans
A23: 3871VG | B23: 53 | D23: Julianalaan | E23: Hoevelaken | N23: JanWillem | O23: Wicherink | P23: 0651079053 | Q23: Actie warmtescans
A24: 3871 CL | B24: 32 | D24: Willem alexanderdreef | E24: Hoevelaken | N24: Paul | O24: Rouwhorst | P24: 0332535207 | Q24: Actie warmtescans
A25: 0 | B25: 0 | D25: Nassaulaan | E25: Hoevelaken | N25: D. | O25: Zijderveld | P25: 0 | Q25: Actie warmtescans
A26: 3871CB | B26: 18 | D26: Asterlaan | E26: Hoevelaken | N26: Jack | O26: Strik | P26: 0614393950 | Q26: Actie warmtescans
A27: 3871CS | B27: 1 | D27: Ottersgat | E27: Hoevelaken | N27: Gerben | O27: dambrink | P27: 0621715979 | Q27: Actie warmtescans
A28: 3871CX | B28: 18 | D28: Nassaulaan | E28: Hoevelaken | N28: Remco | O28: Bloklander | P28: 0618171617 | Q28: Actie warmtescans

Sheet Blad1
A1: postcode | B1: huisnummer | C1: toevoeging | D1: straat | E1: plaats | F1: Aantal | G1: P Geb | H1: Longitude | I1: Latitude | N1: Voornaam | O1: Achternaam | P1: Telefoon | Q1: Projecten
A2: ='hoevelaken-contacten'!G2 -> 0 | B2: ='hoevelaken-contacten'!F2 -> 0 | D2: ='hoevelaken-contacten'!E2 -> 0 | E2: ='hoevelaken-contacten'!H2 -> 0 | N2: ='hoevelaken-contacten'!B2 -> Jos | O2: ='hoevelaken-contacten'!C2 -> Morren | P2: ='hoevelaken-contacten'!D2 -> 65551345 | Q2: ='hoevelaken-contacten'!M2 -> 0
A3: ='hoevelaken-contacten'!G3 -> 3871TD | B3: ='hoevelaken-contacten'!F3 -> 13 | D3: ='hoevelaken-contacten'!E3 -> van Dedemlaan | E3: ='hoevelaken-contacten'!H3 -> Hoevelaken | N3: ='hoevelaken-contacten'!B3 -> René | O3: ='hoevelaken-contacten'!C3 -> Kwee | P3: ='hoevelaken-contacten'!D3 -> 0651174310 | Q3: ='hoevelaken-contacten'!M3 -> Actie warmtescans
A4: ='hoevelaken-contacten'!G4 -> 3871MN | B4: ='hoevelaken-contacten'!F4 -> 37 | D4: ='hoevelaken-contacten'!E4 -> Pastoorakker | E4: ='hoevelaken-contacten'!H4 -> Hoevelaken | N4: ='hoevelaken-contacten'!B4 -> Fridtjof | O4: ='hoevelaken-contacten'!C4 -> Guth | P4: ='hoevelaken-contacten'!D4 -> 0622395427 | Q4: ='hoevelaken-contacten'!M4 -> Actie warmtescans
A5: ='hoevelaken-contacten'!G5 -> 0 | B5: ='hoevelaken-contacten'!F5 -> 0 | D5: ='hoevelaken-contacten'!E5 -> 0 | E5: ='hoevelaken-contacten'!H5 -> 0 | N5: ='hoevelaken-contacten'!B5 -> Willem | O5: ='hoevelaken-contacten'!C5 -> Fontein | P5: ='hoevelaken-contacten'!D5 -> 0654930265 | Q5: ='hoevelaken-contacten'!M5 -> 0
A6: ='hoevelaken-contacten'!G6 -> 0 | B6: ='hoevelaken-contacten'!F6 -> 0 | D6: ='hoevelaken-contacten'!E6 -> 0 | E6: ='hoevelaken-contacten'!H6 -> 0 | N6: ='hoevelaken-contacten'!B6 -> Mark | O6: ='hoevelaken-contacten'!C6 -> de Vos | P6: ='hoevelaken-contacten'!D6 -> 0631004442 | Q6: ='hoevelaken-contacten'!M6 -> Actie warmtescans
A7: ='hoevelaken-contacten'!G7 -> 0 | B7: ='hoevelaken-contacten'!F7 -> 0 | D7: ='hoevelaken-contacten'!E7 -> 0 | E7: ='hoevelaken-contacten'!H7 -> 0 | N7: ='hoevelaken-contacten'!B7 -> Monique | O7: ='hoevelaken-contacten'!C7 -> Spaans | P7: ='hoevelaken-contacten'!D7 -> 0618584171 | Q7: ='hoevelaken-contacten'!M7 -> 0
A8: ='hoevelaken-contacten'!G8 -> 0 | B8: ='hoevelaken-contacten'!F8 -> 0 | D8: ='hoevelaken-contacten'!E8 -> 0 | E8: ='hoevelaken-contacten'!H8 -> 0 | N8: ='hoevelaken-contacten'!B8 -> Resa | O8: ='hoevelaken-contacten'!C8 -> Van den Bunt | P8: ='hoevelaken-contacten'!D8 -> 0620360637 | Q8: ='hoevelaken-contacten'!M8 -> 0
A9: ='hoevelaken-contacten'!G9 -> 0 | B9: ='hoevelaken-contacten'!F9 -> 0 | D9: ='hoevelaken-contacten'!E9 -> 0 | E9: ='hoevelaken-contacten'!H9 -> 0 | N9: ='hoevelaken-contacten'!B9 -> Gé | O9: ='hoevelaken-contacten'!C9 -> Schaeffer | P9: ='hoevelaken-contacten'!D9 -> 0622482339 | Q9: ='hoevelaken-contacten'!M9 -> 0
A10: ='hoevelaken-contacten'!G10 -> 0 | B10: ='hoevelaken-contacten'!F10 -> 0 | D10: ='hoevelaken-contacten'!E10 -> 0 | E10: ='hoevelaken-contacten'!H10 -> 0 | N10: ='hoevelaken-contacten'!B10 -> Elles | O10: ='hoevelaken-contacten'!C10 -> van der Loo | P10: ='hoevelaken-contacten'!D10 -> 0 | Q10: ='hoevelaken-contacten'!M10 -> 0
A11: ='hoevelaken-contacten'!G11 -> 0 | B11: ='hoevelaken-contacten'!F11 -> 0 | D11: ='hoevelaken-contacten'!E11 -> 0 | E11: ='hoevelaken-contacten'!H11 -> 0 | N11: ='hoevelaken-contacten'!B11 -> Manu | O11: ='hoevelaken-contacten'!C11 -> van Essen | P11: ='hoevelaken-contacten'!D11 -> 0 | Q11: ='hoevelaken-contacten'!M11 -> 0
A12: ='hoevelaken-contacten'!G12 -> 0 | B12: ='hoevelaken-contacten'!F12 -> 0 | D12: ='hoevelaken-contacten'!E12 -> 0 | E12: ='hoevelaken-contacten'!H12 -> 0 | N12: ='hoevelaken-contacten'!B12 -> Mina | O12: ='hoevelaken-contacten'!C12 -> vV | P12: ='hoevelaken-contacten'!D12 -> 0 | Q12: ='hoevelaken-contacten'!M12 -> 0
A13: ='hoevelaken-contacten'!G13 -> 0 | B13: ='hoevelaken-contacten'!F13 -> 0 | D13: ='hoevelaken-contacten'!E13 -> 0 | E13: ='hoevelaken-contacten'!H13 -> 0 | N13: ='hoevelaken-contacten'!B13 -> Bertha | O13: ='hoevelaken-contacten'!C13 -> Top | P13: ='hoevelaken-contacten'!D13 -> 0630093672 | Q13: ='hoevelaken-contacten'!M13 -> 0
... A58: ='hoevelaken-contacten'!G58 -> 0 | B58: ='hoevelaken-contacten'!F58 -> 0 | D58: ='hoevelaken-contacten'!E58 -> 0 | E58: ='hoevelaken-contacten'!H58 -> 0 | N58: ='hoevelaken-contacten'!B58 -> 0 | O58: ='hoevelaken-contacten'!C58 -> 0 | P58: ='hoevelaken-contacten'!D58 -> 0 | Q58: ='hoevelaken-contacten'!M58 -> 0
B59: ='hoevelaken-contacten'!F59 -> 0 | D59: ='hoevelaken-contacten'!E59 -> 0 | E59: ='hoevelaken-contacten'!H59 -> 0 | N59: ='hoevelaken-contacten'!B59 -> 0 | O59: ='hoevelaken-contacten'!C59 -> 0 | P59: ='hoevelaken-contacten'!D59 -> 0 | Q59: ='hoevelaken-contacten'!M59 -> 0
B60: ='hoevelaken-contacten'!F60 -> 0 | E60: ='hoevelaken-contacten'!H60 -> 0 | N60: ='hoevelaken-contacten'!B60 -> 0 | O60: ='hoevelaken-contacten'!C60 -> 0 | P60: ='hoevelaken-contacten'!D60 -> 0 | Q60: ='hoevelaken-contacten'!M60 -> 0
B61: ='hoevelaken-contacten'!F61 -> 0 | E61: ='hoevelaken-contacten'!H61 -> 0 | N61: ='hoevelaken-contacten'!B61 -> 0 | O61: ='hoevelaken-contacten'!C61 -> 0 | P61: ='hoevelaken-contacten'!D61 -> 0 | Q61: ='hoevelaken-contacten'!M61 -> 0
B62: ='hoevelaken-contacten'!F62 -> 0 | E62: ='hoevelaken-contacten'!H62 -> 0 | N62: ='hoevelaken-contacten'!B62 -> 0 | O62: ='hoevelaken-contacten'!C62 -> 0 | P62: ='hoevelaken-contacten'!D62 -> 0 | Q62: ='hoevelaken-contacten'!M62 -> 0
B63: ='hoevelaken-contacten'!F63 -> 0 | E63: ='hoevelaken-contacten'!H63 -> 0 | N63: ='hoevelaken-contacten'!B63 -> 0 | O63: ='hoevelaken-contacten'!C63 -> 0 | P63: ='hoevelaken-contacten'!D63 -> 0 | Q63: ='hoevelaken-contacten'!M63 -> 0
B64: ='hoevelaken-contacten'!F64 -> 0 | E64: ='hoevelaken-contacten'!H64 -> 0 | N64: ='hoevelaken-contacten'!B64 -> 0 | O64: ='hoevelaken-contacten'!C64 -> 0 | P64: ='hoevelaken-contacten'!D64 -> 0 | Q64: ='hoevelaken-contacten'!M64 -> 0
B65: ='hoevelaken-contacten'!F65 -> 0 | E65: ='hoevelaken-contacten'!H65 -> 0 | N65: ='hoevelaken-contacten'!B65 -> 0 | O65: ='hoevelaken-contacten'!C65 -> 0 | P65: ='hoevelaken-contacten'!D65 -> 0 | Q65: ='hoevelaken-contacten'!M65 -> 0
B66: ='hoevelaken-contacten'!F66 -> 0 | E66: ='hoevelaken-contacten'!H66 -> 0 | N66: ='hoevelaken-contacten'!B66 -> 0 | O66: ='hoevelaken-contacten'!C66 -> 0 | P66: ='hoevelaken-contacten'!D66 -> 0 | Q66: ='hoevelaken-contacten'!M66 -> 0
B67: ='hoevelaken-contacten'!F67 -> 0 | E67: ='hoevelaken-contacten'!H67 -> 0 | N67: ='hoevelaken-contacten'!B67 -> 0 | O67: ='hoevelaken-contacten'!C67 -> 0 | P67: ='hoevelaken-contacten'!D67 -> 0
B68: ='hoevelaken-contacten'!F68 -> 0 | E68: ='hoevelaken-contacten'!H68 -> 0 | N68: ='hoevelaken-contacten'!B68 -> 0 | O68: ='hoevelaken-contacten'!C68 -> 0 | P68: ='hoevelaken-contacten'!D68 -> 0
B69: ='hoevelaken-contacten'!F69 -> 0 | E69: ='hoevelaken-contacten'!H69 -> 0 | N69: ='hoevelaken-contacten'!B69 -> 0 | O69: ='hoevelaken-contacten'!C69 -> 0 | P69: ='hoevelaken-contacten'!D69 -> 0
B70: ='hoevelaken-contacten'!F70 -> 0 | E70: ='hoevelaken-contacten'!H70 -> 0 | N70: ='hoevelaken-contacten'!B70 -> 0 | O70: ='hoevelaken-contacten'!C70 -> 0 | P70: ='hoevelaken-contacten'!D70 -> 0
B71: ='hoevelaken-contacten'!F71 -> 0
